[2022-07-02 01:27:34,795] {taskinstance.py:1159} INFO - Dependencies all met for <TaskInstance: Raize_ingestion.check_file scheduled__2022-07-01T00:00:00+00:00 [queued]>
[2022-07-02 01:27:34,805] {taskinstance.py:1159} INFO - Dependencies all met for <TaskInstance: Raize_ingestion.check_file scheduled__2022-07-01T00:00:00+00:00 [queued]>
[2022-07-02 01:27:34,805] {taskinstance.py:1356} INFO - 
--------------------------------------------------------------------------------
[2022-07-02 01:27:34,805] {taskinstance.py:1357} INFO - Starting attempt 1 of 1
[2022-07-02 01:27:34,805] {taskinstance.py:1358} INFO - 
--------------------------------------------------------------------------------
[2022-07-02 01:27:34,818] {taskinstance.py:1377} INFO - Executing <Task(FileSensor): check_file> on 2022-07-01 00:00:00+00:00
[2022-07-02 01:27:34,824] {standard_task_runner.py:52} INFO - Started process 321 to run task
[2022-07-02 01:27:34,826] {standard_task_runner.py:79} INFO - Running: ['***', 'tasks', 'run', 'Raize_ingestion', 'check_file', 'scheduled__2022-07-01T00:00:00+00:00', '--job-id', '13', '--raw', '--subdir', 'DAGS_FOLDER/dag_raizen_ingestion.py', '--cfg-path', '/tmp/tmpqqe36n7c', '--error-file', '/tmp/tmpaf4atnqh']
[2022-07-02 01:27:34,827] {standard_task_runner.py:80} INFO - Job 13: Subtask check_file
[2022-07-02 01:27:34,866] {task_command.py:370} INFO - Running <TaskInstance: Raize_ingestion.check_file scheduled__2022-07-01T00:00:00+00:00 [running]> on host 64b5504179b3
[2022-07-02 01:27:34,928] {taskinstance.py:1571} INFO - Exporting the following env vars:
AIRFLOW_CTX_DAG_OWNER=***
AIRFLOW_CTX_DAG_ID=Raize_ingestion
AIRFLOW_CTX_TASK_ID=check_file
AIRFLOW_CTX_EXECUTION_DATE=2022-07-01T00:00:00+00:00
AIRFLOW_CTX_TRY_NUMBER=1
AIRFLOW_CTX_DAG_RUN_ID=scheduled__2022-07-01T00:00:00+00:00
[2022-07-02 01:27:34,945] {taskinstance.py:1889} ERROR - Task failed with exception
Traceback (most recent call last):
  File "/home/airflow/.local/lib/python3.7/site-packages/airflow/sensors/base.py", line 277, in execute
    poke_return = self.poke(context)
  File "/home/airflow/.local/lib/python3.7/site-packages/airflow/sensors/filesystem.py", line 55, in poke
    hook = FSHook(self.fs_conn_id)
  File "/home/airflow/.local/lib/python3.7/site-packages/airflow/hooks/filesystem.py", line 38, in __init__
    conn = self.get_connection(conn_id)
  File "/home/airflow/.local/lib/python3.7/site-packages/airflow/hooks/base.py", line 67, in get_connection
    conn = Connection.get_connection_from_secrets(conn_id)
  File "/home/airflow/.local/lib/python3.7/site-packages/airflow/models/connection.py", line 430, in get_connection_from_secrets
    raise AirflowNotFoundException(f"The conn_id `{conn_id}` isn't defined")
airflow.exceptions.AirflowNotFoundException: The conn_id `fs_default` isn't defined
[2022-07-02 01:27:34,949] {taskinstance.py:1400} INFO - Marking task as FAILED. dag_id=Raize_ingestion, task_id=check_file, execution_date=20220701T000000, start_date=20220702T012734, end_date=20220702T012734
[2022-07-02 01:27:34,958] {standard_task_runner.py:97} ERROR - Failed to execute job 13 for task check_file (The conn_id `fs_default` isn't defined; 321)
[2022-07-02 01:27:34,998] {local_task_job.py:156} INFO - Task exited with return code 1
[2022-07-02 01:27:35,032] {local_task_job.py:273} INFO - 0 downstream tasks scheduled from follow-on schedule check
